2017-06-13 11:32:12 ERROR (Thread-7) [homeassistant.components.device_tracker.tplink] Couldn't fetch auth tokens! Response was: <Script language=JavaScript>
var errorCode = 501;
var errorNote = "<p>File not found</p>";
var homeSite = "http://192.168.0.1";
</script>
<HTML>
<HEAD>
<TITLE>Error</TITLE>
<META http-equiv="Content-Type" content="text/html; charset=iso-8859-1">
</HEAD>
<BODY>
<DIV style="padding:0px 30px;">
<script type="text/javascript">
function goHome()
{
	window.parent.location.href = homeSite;
}
document.write("<h1>" + errorCode +"</h1><hr>");
document.write(errorNote);
</script>
<p><a href="#" onClick="goHome()">Go Home</a></p>
</DIV>
</BODY>
</HTML>
2017-06-13 11:32:12 ERROR (Thread-7) [homeassistant.components.device_tracker.tplink] Router didn't respond with JSON. Check if credentials are correct
2017-06-13 11:32:16 ERROR (MainThread) [homeassistant.components.media_player] Error while setting up platform plex
Traceback (most recent call last):
  File "/srv/homeassistant/lib/python3.4/site-packages/homeassistant/helpers/entity_component.py", line 160, in _async_setup_platform
    SLOW_SETUP_MAX_WAIT, loop=self.hass.loop)
  File "/usr/lib/python3.4/asyncio/tasks.py", line 372, in wait_for
    return fut.result()
  File "/usr/lib/python3.4/asyncio/futures.py", line 277, in result
    raise self._exception
  File "/usr/lib/python3.4/concurrent/futures/thread.py", line 54, in run
    result = self.fn(*self.args, **self.kwargs)
  File "/home/homeassistant/.homeassistant/custom_components/media_player/plex.py", line 81, in setup_platform
    file_config = config_from_file(hass.config.path(PLEX_CONFIG_FILE))
  File "/home/homeassistant/.homeassistant/custom_components/media_player/plex.py", line 69, in config_from_file
    return json.loads(fdesc.read())
  File "/usr/lib/python3.4/json/__init__.py", line 318, in loads
    return _default_decoder.decode(s)
  File "/usr/lib/python3.4/json/decoder.py", line 343, in decode
    obj, end = self.raw_decode(s, idx=_w(s, 0).end())
  File "/usr/lib/python3.4/json/decoder.py", line 361, in raw_decode
    raise ValueError(errmsg("Expecting value", s, err.value)) from None
ValueError: Expecting value: line 1 column 1 (char 0)
2017-06-13 11:32:19 WARNING (MainThread) [homeassistant.setup] Setup of remote is taking over 10 seconds.
2017-06-13 11:32:24 WARNING (MainThread) [homeassistant.components.remote] Setup of platform harmony is taking over 10 seconds.
2017-06-13 11:32:50 ERROR (MainThread) [homeassistant.core] Error doing job: Task exception was never retrieved
Traceback (most recent call last):
  File "/usr/lib/python3.4/asyncio/tasks.py", line 237, in _step
    result = next(coro)
  File "/srv/homeassistant/lib/python3.4/site-packages/homeassistant/core.py", line 1015, in _event_to_service_call
    yield from service_handler.func(service_call)
  File "/srv/homeassistant/lib/python3.4/site-packages/homeassistant/components/script.py", line 116, in turn_off_service
    in component.async_extract_from_service(service)], loop=hass.loop)
  File "/usr/lib/python3.4/asyncio/tasks.py", line 322, in wait
    raise ValueError('Set of coroutines/Futures is empty.')
ValueError: Set of coroutines/Futures is empty.
2017-06-13 11:32:50 WARNING (Thread-3) [netdisco.ssdp] Error fetching description at 192.168.0.113
2017-06-13 11:32:50 WARNING (Thread-3) [netdisco.ssdp] Error fetching description at 192.168.0.114
2017-06-13 11:32:53 ERROR (MainThread) [homeassistant.components.media_player] Error while setting up platform plex
Traceback (most recent call last):
  File "/srv/homeassistant/lib/python3.4/site-packages/homeassistant/helpers/entity_component.py", line 160, in _async_setup_platform
    SLOW_SETUP_MAX_WAIT, loop=self.hass.loop)
  File "/usr/lib/python3.4/asyncio/tasks.py", line 372, in wait_for
    return fut.result()
  File "/usr/lib/python3.4/asyncio/futures.py", line 277, in result
    raise self._exception
  File "/usr/lib/python3.4/concurrent/futures/thread.py", line 54, in run
    result = self.fn(*self.args, **self.kwargs)
  File "/home/homeassistant/.homeassistant/custom_components/media_player/plex.py", line 81, in setup_platform
    file_config = config_from_file(hass.config.path(PLEX_CONFIG_FILE))
  File "/home/homeassistant/.homeassistant/custom_components/media_player/plex.py", line 69, in config_from_file
    return json.loads(fdesc.read())
  File "/usr/lib/python3.4/json/__init__.py", line 318, in loads
    return _default_decoder.decode(s)
  File "/usr/lib/python3.4/json/decoder.py", line 343, in decode
    obj, end = self.raw_decode(s, idx=_w(s, 0).end())
  File "/usr/lib/python3.4/json/decoder.py", line 361, in raw_decode
    raise ValueError(errmsg("Expecting value", s, err.value)) from None
ValueError: Expecting value: line 1 column 1 (char 0)
